<?xml version="1.0"?>
<robot xmlns:xacro="http://www.ros.org/wiki/xacro" name="cara">

  <link name="base_link"/>

  <link name="torso">
    <inertial>
      <mass value="2.5"/> <inertia ixx="0.01" ixy="0" ixz="0" iyy="0.01" iyz="0" izz="0.01"/>
    </inertial>
  </link>

  <joint name="base_to_torso" type="fixed">
    <parent link="base_link"/>
    <child link="torso"/>
  </joint>

  <xacro:macro name="waist_joint" params="suffix axis">
    <joint name="waist_${suffix}" type="revolute">
      <parent link="torso"/>
      <child link="waist_link_${suffix}"/>
      <axis xyz="${axis}"/>
      <limit lower="-0.7" upper="0.7" effort="10" velocity="1.0"/>
    </joint>
  </xacro:macro>

  </robot>
